Workbook

Sheet Calendario
A1: ASSENZE COLLEGIO
A2: ="Periodo: "&TEXT(DAY(Impostazioni!$B$4),"00")&"/"&TEXT(MONTH(Impostazioni!$B$4),"00")&"/"&YEAR(Impostazioni!$B$4)&" - "&TEXT(DAY(Impostazioni!$B$5),"00")&"/"&TEXT(MONTH(Impostazioni!$B$5),"00")&"/"&YEAR(Impostazioni!$B$5)&" · soglia "&ROUND(Impostazioni!$B$6*100,0)&"%" -> Periodo: 01/10/2026 - 30/09/2027 · soglia 56% | J2: =Impostazioni!$B$8 -> 46298
A3: ASSENZE RIMANENTI | C3: MENSILI RIMANENTI | F3: PRESENZA A FINE ANNO
A4: =Riepilogo!B17 -> 137 | C4: =Riepilogo!B29 -> 12.528 | F4: =Riepilogo!B24 -> 1
A5: ="Assenze usate "&Riepilogo!B15&" su "&Riepilogo!B12&" · Giustificate "&Riepilogo!B16&" · Presenze finora "&Riepilogo!B21 -> Assenze usate 0 su 137 · Giustificate 0 · Presenze finora 2
A6: =IF(Impostazioni!$B$12<>"OK","VERIFICA IMPOSTAZIONI",IF(Riepilogo!B17<0,"SOGLIA SUPERATA",IF(Riepilogo!B17<=Impostazioni!$B$10,"ATTENZIONE: POCHE ASSENZE RIMASTE","IN REGOLA"))) -> IN REGOLA
A7: Ogni giorno è già presenza: segna solo le assenze. Tocca la cella sotto la data e scegli A, G o P.
A8: A | B8: G | C8: P | D8: festa / chiuso
A9: A assenza · G giustificata (conta come presenza) · P presente (annulla un'assenza) · verde = presenza
A10: =HYPERLINK("#Calendario!A"&(14+15*MAX(0,MIN(11,(YEAR(Impostazioni!$B$8)-YEAR(Impostazioni!$B$11))*12+MONTH(Impostazioni!$B$8)-MONTH(Impostazioni!$B$11)))),"▸ VAI AL MESE CORRENTE") -> ▸ VAI AL MESE CORRENTE
A11: =HYPERLINK("#Calendario!A14",CHOOSE(MONTH($J$14),"Gen","Feb","Mar","Apr","Mag","Giu","Lug","Ago","Set","Ott","Nov","Dic")&" "&TEXT(MOD(YEAR($J$14),100),"00")) -> Ott 26 | B11: =HYPERLINK("#Calendario!A29",CHOOSE(MONTH($J$29),"Gen","Feb","Mar","Apr","Mag","Giu","Lug","Ago","Set","Ott","Nov","Dic")&" "&TEXT(MOD(YEAR($J$29),100),"00")) -> Nov 26 | C11: =HYPERLINK("#Calendario!A44",CHOOSE(MONTH($J$44),"Gen","Feb","Mar","Apr","Mag","Giu","Lug","Ago","Set","Ott","Nov","Dic")&" "&TEXT(MOD(YEAR($J$44),100),"00")) -> Dic 26 | D11: =HYPERLINK("#Calendario!A59",CHOOSE(MONTH($J$59),"Gen","Feb","Mar","Apr","Mag","Giu","Lug","Ago","Set","Ott","Nov","Dic")&" "&TEXT(MOD(YEAR($J$59),100),"00")) -> Gen 27 | E11: =HYPERLINK("#Calendario!A74",CHOOSE(MONTH($J$74),"Gen","Feb","Mar","Apr","Mag","Giu","Lug","Ago","Set","Ott","Nov","Dic")&" "&TEXT(MOD(YEAR($J$74),100),"00")) -> Feb 27 | F11: =HYPERLINK("#Calendario!A89",CHOOSE(MONTH($J$89),"Gen","Feb","Mar","Apr","Mag","Giu","Lug","Ago","Set","Ott","Nov","Dic")&" "&TEXT(MOD(YEAR($J$89),100),"00")) -> Mar 27 | G11: =HYPERLINK("#Calendario!A104",CHOOSE(MONTH($J$104),"Gen","Feb","Mar","Apr","Mag","Giu","Lug","Ago","Set","Ott","Nov","Dic")&" "&TEXT(MOD(YEAR($J$104),100),"00")) -> Apr 27
A12: =HYPERLINK("#Calendario!A119",CHOOSE(MONTH($J$119),"Gen","Feb","Mar","Apr","Mag","Giu","Lug","Ago","Set","Ott","Nov","Dic")&" "&TEXT(MOD(YEAR($J$119),100),"00")) -> Mag 27 | B12: =HYPERLINK("#Calendario!A134",CHOOSE(MONTH($J$134),"Gen","Feb","Mar","Apr","Mag","Giu","Lug","Ago","Set","Ott","Nov","Dic")&" "&TEXT(MOD(YEAR($J$134),100),"00")) -> Giu 27 | C12: =HYPERLINK("#Calendario!A149",CHOOSE(MONTH($J$149),"Gen","Feb","Mar","Apr","Mag","Giu","Lug","Ago","Set","Ott","Nov","Dic")&" "&TEXT(MOD(YEAR($J$149),100),"00")) -> Lug 27 | D12: =HYPERLINK("#Calendario!A164",CHOOSE(MONTH($J$164),"Gen","Feb","Mar","Apr","Mag","Giu","Lug","Ago","Set","Ott","Nov","Dic")&" "&TEXT(MOD(YEAR($J$164),100),"00")) -> Ago 27 | E12: =HYPERLINK("#Calendario!A179",CHOOSE(MONTH($J$179),"Gen","Feb","Mar","Apr","Mag","Giu","Lug","Ago","Set","Ott","Nov","Dic")&" "&TEXT(MOD(YEAR($J$179),100),"00")) -> Set 27
A14: =CHOOSE(MONTH($J14),"GENNAIO","FEBBRAIO","MARZO","APRILE","MAGGIO","GIUGNO","LUGLIO","AGOSTO","SETTEMBRE","OTTOBRE","NOVEMBRE","DICEMBRE")&" "&YEAR($J14) -> OTTOBRE 2026 | J14: =Impostazioni!$B$11 -> 46296
A15: L | B15: M | C15: M | D15: G | E15: V | F15: S | G15: D
A16: =IF(MONTH($J$14-WEEKDAY($J$14,2)+1)=MONTH($J$14),$J$14-WEEKDAY($J$14,2)+1,"") | B16: =IF(MONTH($J$14-WEEKDAY($J$14,2)+2)=MONTH($J$14),$J$14-WEEKDAY($J$14,2)+2,"") | C16: =IF(MONTH($J$14-WEEKDAY($J$14,2)+3)=MONTH($J$14),$J$14-WEEKDAY($J$14,2)+3,"") | D16: =IF(MONTH($J$14-WEEKDAY($J$14,2)+4)=MONTH($J$14),$J$14-WEEKDAY($J$14,2)+4,"") -> 46296 | E16: =IF(MONTH($J$14-WEEKDAY($J$14,2)+5)=MONTH($J$14),$J$14-WEEKDAY($J$14,2)+5,"") -> 46297 | F16: =IF(MONTH($J$14-WEEKDAY($J$14,2)+6)=MONTH($J$14),$J$14-WEEKDAY($J$14,2)+6,"") -> 46298 | G16: =IF(MONTH($J$14-WEEKDAY($J$14,2)+7)=MONTH($J$14),$J$14-WEEKDAY($J$14,2)+7,"") -> 46299 | K16: =IF(A16="","",INDEX(Giorni!$M$2:$M$367,A16-Giorni!$A$2+1)) | L16: =IF(B16="","",INDEX(Giorni!$M$2:$M$367,B16-Giorni!$A$2+1)) | M16: =IF(C16="","",INDEX(Giorni!$M$2:$M$367,C16-Giorni!$A$2+1)) | N16: =IF(D16="","",INDEX(Giorni!$M$2:$M$367,D16-Giorni!$A$2+1)) -> 0 | O16: =IF(E16="","",INDEX(Giorni!$M$2:$M$367,E16-Giorni!$A$2+1)) -> 0 | P16: =IF(F16="","",INDEX(Giorni!$M$2:$M$367,F16-Giorni!$A$2+1)) -> 1 | Q16: =IF(G16="","",INDEX(Giorni!$M$2:$M$367,G16-Giorni!$A$2+1)) -> 1
A18: =IF(MONTH($J$14-WEEKDAY($J$14,2)+8)=MONTH($J$14),$J$14-WEEKDAY($J$14,2)+8,"") -> 46300 | B18: =IF(MONTH($J$14-WEEKDAY($J$14,2)+9)=MONTH($J$14),$J$14-WEEKDAY($J$14,2)+9,"") -> 46301 | C18: =IF(MONTH($J$14-WEEKDAY($J$14,2)+10)=MONTH($J$14),$J$14-WEEKDAY($J$14,2)+10,"") -> 46302 | D18: =IF(MONTH($J$14-WEEKDAY($J$14,2)+11)=MONTH($J$14),$J$14-WEEKDAY($J$14,2)+11,"") -> 46303 | E18: =IF(MONTH($J$14-WEEKDAY($J$14,2)+12)=MONTH($J$14),$J$14-WEEKDAY($J$14,2)+12,"") -> 46304 | F18: =IF(MONTH($J$14-WEEKDAY($J$14,2)+13)=MONTH($J$14),$J$14-WEEKDAY($J$14,2)+13,"") -> 46305 | G18: =IF(MONTH($J$14-WEEKDAY($J$14,2)+14)=MONTH($J$14),$J$14-WEEKDAY($J$14,2)+14,"") -> 46306 | K18: =IF(A18="","",INDEX(Giorni!$M$2:$M$367,A18-Giorni!$A$2+1)) -> 0 | L18: =IF(B18="","",INDEX(Giorni!$M$2:$M$367,B18-Giorni!$A$2+1)) -> 0 | M18: =IF(C18="","",INDEX(Giorni!$M$2:$M$367,C18-Giorni!$A$2+1)) -> 0 | N18: =IF(D18="","",INDEX(Giorni!$M$2:$M$367,D18-Giorni!$A$2+1)) -> 0 | O18: =IF(E18="","",INDEX(Giorni!$M$2:$M$367,E18-Giorni!$A$2+1)) -> 0 | P18: =IF(F18="","",INDEX(Giorni!$M$2:$M$367,F18-Giorni!$A$2+1)) -> 1 | Q18: =IF(G18="","",INDEX(Giorni!$M$2:$M$367,G18-Giorni!$A$2+1)) -> 1
A20: =IF(MONTH($J$14-WEEKDAY($J$14,2)+15)=MONTH($J$14),$J$14-WEEKDAY($J$14,2)+15,"") -> 46307 | B20: =IF(MONTH($J$14-WEEKDAY($J$14,2)+16)=MONTH($J$14),$J$14-WEEKDAY($J$14,2)+16,"") -> 46308 | C20: =IF(MONTH($J$14-WEEKDAY($J$14,2)+17)=MONTH($J$14),$J$14-WEEKDAY($J$14,2)+17,"") -> 46309 | D20: =IF(MONTH($J$14-WEEKDAY($J$14,2)+18)=MONTH($J$14),$J$14-WEEKDAY($J$14,2)+18,"") -> 46310 | E20: =IF(MONTH($J$14-WEEKDAY($J$14,2)+19)=MONTH($J$14),$J$14-WEEKDAY($J$14,2)+19,"") -> 46311 | F20: =IF(MONTH($J$14-WEEKDAY($J$14,2)+20)=MONTH($J$14),$J$14-WEEKDAY($J$14,2)+20,"") -> 46312 | G20: =IF(MONTH($J$14-WEEKDAY($J$14,2)+21)=MONTH($J$14),$J$14-WEEKDAY($J$14,2)+21,"") -> 46313 | K20: =IF(A20="","",INDEX(Giorni!$M$2:$M$367,A20-Giorni!$A$2+1)) -> 0 | L20: =IF(B20="","",INDEX(Giorni!$M$2:$M$367,B20-Giorni!$A$2+1)) -> 0 | M20: =IF(C20="","",INDEX(Giorni!$M$2:$M$367,C20-Giorni!$A$2+1)) -> 0 | N20: =IF(D20="","",INDEX(Giorni!$M$2:$M$367,D20-Giorni!$A$2+1)) -> 0 | O20: =IF(E20="","",INDEX(Giorni!$M$2:$M$367,E20-Giorni!$A$2+1)) -> 0 | P20: =IF(F20="","",INDEX(Giorni!$M$2:$M$367,F20-Giorni!$A$2+1)) -> 1 | Q20: =IF(G20="","",INDEX(Giorni!$M$2:$M$367,G20-Giorni!$A$2+1)) -> 1
A22: =IF(MONTH($J$14-WEEKDAY($J$14,2)+22)=MONTH($J$14),$J$14-WEEKDAY($J$14,2)+22,"") -> 46314 | B22: =IF(MONTH($J$14-WEEKDAY($J$14,2)+23)=MONTH($J$14),$J$14-WEEKDAY($J$14,2)+23,"") -> 46315 | C22: =IF(MONTH($J$14-WEEKDAY($J$14,2)+24)=MONTH($J$14),$J$14-WEEKDAY($J$14,2)+24,"") -> 46316 | D22: =IF(MONTH($J$14-WEEKDAY($J$14,2)+25)=MONTH($J$14),$J$14-WEEKDAY($J$14,2)+25,"") -> 46317 | E22: =IF(MONTH($J$14-WEEKDAY($J$14,2)+26)=MONTH($J$14),$J$14-WEEKDAY($J$14,2)+26,"") -> 46318 | F22: =IF(MONTH($J$14-WEEKDAY($J$14,2)+27)=MONTH($J$14),$J$14-WEEKDAY($J$14,2)+27,"") -> 46319 | G22: =IF(MONTH($J$14-WEEKDAY($J$14,2)+28)=MONTH($J$14),$J$14-WEEKDAY($J$14,2)+28,"") -> 46320 | K22: =IF(A22="","",INDEX(Giorni!$M$2:$M$367,A22-Giorni!$A$2+1)) -> 0 | L22: =IF(B22="","",INDEX(Giorni!$M$2:$M$367,B22-Giorni!$A$2+1)) -> 0 | M22: =IF(C22="","",INDEX(Giorni!$M$2:$M$367,C22-Giorni!$A$2+1)) -> 0 | N22: =IF(D22="","",INDEX(Giorni!$M$2:$M$367,D22-Giorni!$A$2+1)) -> 0 | O22: =IF(E22="","",INDEX(Giorni!$M$2:$M$367,E22-Giorni!$A$2+1)) -> 0 | P22: =IF(F22="","",INDEX(Giorni!$M$2:$M$367,F22-Giorni!$A$2+1)) -> 1 | Q22: =IF(G22="","",INDEX(Giorni!$M$2:$M$367,G22-Giorni!$A$2+1)) -> 1
A24: =IF(MONTH($J$14-WEEKDAY($J$14,2)+29)=MONTH($J$14),$J$14-WEEKDAY($J$14,2)+29,"") -> 46321 | B24: =IF(MONTH($J$14-WEEKDAY($J$14,2)+30)=MONTH($J$14),$J$14-WEEKDAY($J$14,2)+30,"") -> 46322 | C24: =IF(MONTH($J$14-WEEKDAY($J$14,2)+31)=MONTH($J$14),$J$14-WEEKDAY($J$14,2)+31,"") -> 46323 | D24: =IF(MONTH($J$14-WEEKDAY($J$14,2)+32)=MONTH($J$14),$J$14-WEEKDAY($J$14,2)+32,"") -> 46324 | E24: =IF(MONTH($J$14-WEEKDAY($J$14,2)+33)=MONTH($J$14),$J$14-WEEKDAY($J$14,2)+33,"") -> 46325 | F24: =IF(MONTH($J$14-WEEKDAY($J$14,2)+34)=MONTH($J$14),$J$14-WEEKDAY($J$14,2)+34,"") -> 46326 | G24: =IF(MONTH($J$14-WEEKDAY($J$14,2)+35)=MONTH($J$14),$J$14-WEEKDAY($J$14,2)+35,"") | K24: =IF(A24="","",INDEX(Giorni!$M$2:$M$367,A24-Giorni!$A$2+1)) -> 0 | L24: =IF(B24="","",INDEX(Giorni!$M$2:$M$367,B24-Giorni!$A$2+1)) -> 0 | M24: =IF(C24="","",INDEX(Giorni!$M$2:$M$367,C24-Giorni!$A$2+1)) -> 0 | N24: =IF(D24="","",INDEX(Giorni!$M$2:$M$367,D24-Giorni!$A$2+1)) -> 0 | O24: =IF(E24="","",INDEX(Giorni!$M$2:$M$367,E24-Giorni!$A$2+1)) -> 0 | P24: =IF(F24="","",INDEX(Giorni!$M$2:$M$367,F24-Giorni!$A$2+1)) -> 1 | Q24: =IF(G24="","",INDEX(Giorni!$M$2:$M$367,G24-Giorni!$A$2+1))
A26: =IF(MONTH($J$14-WEEKDAY($J$14,2)+36)=MONTH($J$14),$J$14-WEEKDAY($J$14,2)+36,"") | B26: =IF(MONTH($J$14-WEEKDAY($J$14,2)+37)=MONTH($J$14),$J$14-WEEKDAY($J$14,2)+37,"") | C26: =IF(MONTH($J$14-WEEKDAY($J$14,2)+38)=MONTH($J$14),$J$14-WEEKDAY($J$14,2)+38,"") | D26: =IF(MONTH($J$14-WEEKDAY($J$14,2)+39)=MONTH($J$14),$J$14-WEEKDAY($J$14,2)+39,"") | E26: =IF(MONTH($J$14-WEEKDAY($J$14,2)+40)=MONTH($J$14),$J$14-WEEKDAY($J$14,2)+40,"") | F26: =IF(MONTH($J$14-WEEKDAY($J$14,2)+41)=MONTH($J$14),$J$14-WEEKDAY($J$14,2)+41,"") | G26: =IF(MONTH($J$14-WEEKDAY($J$14,2)+42)=MONTH($J$14),$J$14-WEEKDAY($J$14,2)+42,"") | K26: =IF(A26="","",INDEX(Giorni!$M$2:$M$367,A26-Giorni!$A$2+1)) | L26: =IF(B26="","",INDEX(Giorni!$M$2:$M$367,B26-Giorni!$A$2+1)) | M26: =IF(C26="","",INDEX(Giorni!$M$2:$M$367,C26-Giorni!$A$2+1)) | N26: =IF(D26="","",INDEX(Giorni!$M$2:$M$367,D26-Giorni!$A$2+1)) | O26: =IF(E26="","",INDEX(Giorni!$M$2:$M$367,E26-Giorni!$A$2+1)) | P26: =IF(F26="","",INDEX(Giorni!$M$2:$M$367,F26-Giorni!$A$2+1)) | Q26: =IF(G26="","",INDEX(Giorni!$M$2:$M$367,G26-Giorni!$A$2+1))
A29: =CHOOSE(MONTH($J29),"GENNAIO","FEBBRAIO","MARZO","APRILE","MAGGIO","GIUGNO","LUGLIO","AGOSTO","SETTEMBRE","OTTOBRE","NOVEMBRE","DICEMBRE")&" "&YEAR($J29) -> NOVEMBRE 2026 | J29: =EDATE(J14,1) -> 46327
A30: L | B30: M | C30: M | D30: G | E30: V | F30: S | G30: D
A31: =IF(MONTH($J$29-WEEKDAY($J$29,2)+1)=MONTH($J$29),$J$29-WEEKDAY($J$29,2)+1,"") | B31: =IF(MONTH($J$29-WEEKDAY($J$29,2)+2)=MONTH($J$29),$J$29-WEEKDAY($J$29,2)+2,"") | C31: =IF(MONTH($J$29-WEEKDAY($J$29,2)+3)=MONTH($J$29),$J$29-WEEKDAY($J$29,2)+3,"") | D31: =IF(MONTH($J$29-WEEKDAY($J$29,2)+4)=MONTH($J$29),$J$29-WEEKDAY($J$29,2)+4,"") | E31: =IF(MONTH($J$29-WEEKDAY($J$29,2)+5)=MONTH($J$29),$J$29-WEEKDAY($J$29,2)+5,"") | F31: =IF(MONTH($J$29-WEEKDAY($J$29,2)+6)=MONTH($J$29),$J$29-WEEKDAY($J$29,2)+6,"") | G31: =IF(MONTH($J$29-WEEKDAY($J$29,2)+7)=MONTH($J$29),$J$29-WEEKDAY($J$29,2)+7,"") -> 46327 | K31: =IF(A31="","",INDEX(Giorni!$M$2:$M$367,A31-Giorni!$A$2+1)) | L31: =IF(B31="","",INDEX(Giorni!$M$2:$M$367,B31-Giorni!$A$2+1)) | M31: =IF(C31="","",INDEX(Giorni!$M$2:$M$367,C31-Giorni!$A$2+1)) | N31: =IF(D31="","",INDEX(Giorni!$M$2:$M$367,D31-Giorni!$A$2+1)) | O31: =IF(E31="","",INDEX(Giorni!$M$2:$M$367,E31-Giorni!$A$2+1)) | P31: =IF(F31="","",INDEX(Giorni!$M$2:$M$367,F31-Giorni!$A$2+1)) | Q31: =IF(G31="","",INDEX(Giorni!$M$2:$M$367,G31-Giorni!$A$2+1)) -> 2
A33: =IF(MONTH($J$29-WEEKDAY($J$29,2)+8)=MONTH($J$29),$J$29-WEEKDAY($J$29,2)+8,"") -> 46328 | B33: =IF(MONTH($J$29-WEEKDAY($J$29,2)+9)=MONTH($J$29),$J$29-WEEKDAY($J$29,2)+9,"") -> 46329 | C33: =IF(MONTH($J$29-WEEKDAY($J$29,2)+10)=MONTH($J$29),$J$29-WEEKDAY($J$29,2)+10,"") -> 46330 | D33: =IF(MONTH($J$29-WEEKDAY($J$29,2)+11)=MONTH($J$29),$J$29-WEEKDAY($J$29,2)+11,"") -> 46331 | E33: =IF(MONTH($J$29-WEEKDAY($J$29,2)+12)=MONTH($J$29),$J$29-WEEKDAY($J$29,2)+12,"") -> 46332 | F33: =IF(MONTH($J$29-WEEKDAY($J$29,2)+13)=MONTH($J$29),$J$29-WEEKDAY($J$29,2)+13,"") -> 46333 | G33: =IF(MONTH($J$29-WEEKDAY($J$29,2)+14)=MONTH($J$29),$J$29-WEEKDAY($J$29,2)+14,"") -> 46334 | K33: =IF(A33="","",INDEX(Giorni!$M$2:$M$367,A33-Giorni!$A$2+1)) -> 0 | L33: =IF(B33="","",INDEX(Giorni!$M$2:$M$367,B33-Giorni!$A$2+1)) -> 0 | M33: =IF(C33="","",INDEX(Giorni!$M$2:$M$367,C33-Giorni!$A$2+1)) -> 0 | N33: =IF(D33="","",INDEX(Giorni!$M$2:$M$367,D33-Giorni!$A$2+1)) -> 0 | O33: =IF(E33="","",INDEX(Giorni!$M$2:$M$367,E33-Giorni!$A$2+1)) -> 0 | P33: =IF(F33="","",INDEX(Giorni!$M$2:$M$367,F33-Giorni!$A$2+1)) -> 1 | Q33: =IF(G33="","",INDEX(Giorni!$M$2:$M$367,G33-Giorni!$A$2+1)) -> 1
A35: =IF(MONTH($J$29-WEEKDAY($J$29,2)+15)=MONTH($J$29),$J$29-WEEKDAY($J$29,2)+15,"") -> 46335 | B35: =IF(MONTH($J$29-WEEKDAY($J$29,2)+16)=MONTH($J$29),$J$29-WEEKDAY($J$29,2)+16,"") -> 46336 | C35: =IF(MONTH($J$29-WEEKDAY($J$29,2)+17)=MONTH($J$29),$J$29-WEEKDAY($J$29,2)+17,"") -> 46337 | D35: =IF(MONTH($J$29-WEEKDAY($J$29,2)+18)=MONTH($J$29),$J$29-WEEKDAY($J$29,2)+18,"") -> 46338 | E35: =IF(MONTH($J$29-WEEKDAY($J$29,2)+19)=MONTH($J$29),$J$29-WEEKDAY($J$29,2)+19,"") -> 46339 | F35: =IF(MONTH($J$29-WEEKDAY($J$29,2)+20)=MONTH($J$29),$J$29-WEEKDAY($J$29,2)+20,"") -> 46340 | G35: =IF(MONTH($J$29-WEEKDAY($J$29,2)+21)=MONTH($J$29),$J$29-WEEKDAY($J$29,2)+21,"") -> 46341 | K35: =IF(A35="","",INDEX(Giorni!$M$2:$M$367,A35-Giorni!$A$2+1)) -> 0 | L35: =IF(B35="","",INDEX(Giorni!$M$2:$M$367,B35-Giorni!$A$2+1)) -> 0 | M35: =IF(C35="","",INDEX(Giorni!$M$2:$M$367,C35-Giorni!$A$2+1)) -> 0 | N35: =IF(D35="","",INDEX(Giorni!$M$2:$M$367,D35-Giorni!$A$2+1)) -> 0 | O35: =IF(E35="","",INDEX(Giorni!$M$2:$M$367,E35-Giorni!$A$2+1)) -> 0 | P35: =IF(F35="","",INDEX(Giorni!$M$2:$M$367,F35-Giorni!$A$2+1)) -> 1 | Q35: =IF(G35="","",INDEX(Giorni!$M$2:$M$367,G35-Giorni!$A$2+1)) -> 1
A37: =IF(MONTH($J$29-WEEKDAY($J$29,2)+22)=MONTH($J$29),$J$29-WEEKDAY($J$29,2)+22,"") -> 46342 | B37: =IF(MONTH($J$29-WEEKDAY($J$29,2)+23)=MONTH($J$29),$J$29-WEEKDAY($J$29,2)+23,"") -> 46343 | C37: =IF(MONTH($J$29-WEEKDAY($J$29,2)+24)=MONTH($J$29),$J$29-WEEKDAY($J$29,2)+24,"") -> 46344 | D37: =IF(MONTH($J$29-WEEKDAY($J$29,2)+25)=MONTH($J$29),$J$29-WEEKDAY($J$29,2)+25,"") -> 46345 | E37: =IF(MONTH($J$29-WEEKDAY($J$29,2)+26)=MONTH($J$29),$J$29-WEEKDAY($J$29,2)+26,"") -> 46346 | F37: =IF(MONTH($J$29-WEEKDAY($J$29,2)+27)=MONTH($J$29),$J$29-WEEKDAY($J$29,2)+27,"") -> 46347 | G37: =IF(MONTH($J$29-WEEKDAY($J$29,2)+28)=MONTH($J$29),$J$29-WEEKDAY($J$29,2)+28,"") -> 46348 | K37: =IF(A37="","",INDEX(Giorni!$M$2:$M$367,A37-Giorni!$A$2+1)) -> 0 | L37: =IF(B37="","",INDEX(Giorni!$M$2:$M$367,B37-Giorni!$A$2+1)) -> 0 | M37: =IF(C37="","",INDEX(Giorni!$M$2:$M$367,C37-Giorni!$A$2+1)) -> 0 | N37: =IF(D37="","",INDEX(Giorni!$M$2:$M$367,D37-Giorni!$A$2+1)) -> 0 | O37: =IF(E37="","",INDEX(Giorni!$M$2:$M$367,E37-Giorni!$A$2+1)) -> 0 | P37: =IF(F37="","",INDEX(Giorni!$M$2:$M$367,F37-Giorni!$A$2+1)) -> 1 | Q37: =IF(G37="","",INDEX(Giorni!$M$2:$M$367,G37-Giorni!$A$2+1)) -> 1
A39: =IF(MONTH($J$29-WEEKDAY($J$29,2)+29)=MONTH($J$29),$J$29-WEEKDAY($J$29,2)+29,"") -> 46349 | B39: =IF(MONTH($J$29-WEEKDAY($J$29,2)+30)=MONTH($J$29),$J$29-WEEKDAY($J$29,2)+30,"") -> 46350 | C39: =IF(MONTH($J$29-WEEKDAY($J$29,2)+31)=MONTH($J$29),$J$29-WEEKDAY($J$29,2)+31,"") -> 46351 | D39: =IF(MONTH($J$29-WEEKDAY($J$29,2)+32)=MONTH($J$29),$J$29-WEEKDAY($J$29,2)+32,"") -> 46352 | E39: =IF(MONTH($J$29-WEEKDAY($J$29,2)+33)=MONTH($J$29),$J$29-WEEKDAY($J$29,2)+33,"") -> 46353 | F39: =IF(MONTH($J$29-WEEKDAY($J$29,2)+34)=MONTH($J$29),$J$29-WEEKDAY($J$29,2)+34,"") -> 46354 | G39: =IF(MONTH($J$29-WEEKDAY($J$29,2)+35)=MONTH($J$29),$J$29-WEEKDAY($J$29,2)+35,"") -> 46355 | K39: =IF(A39="","",INDEX(Giorni!$M$2:$M$367,A39-Giorni!$A$2+1)) -> 0 | L39: =IF(B39="","",INDEX(Giorni!$M$2:$M$367,B39-Giorni!$A$2+1)) -> 0 | M39: =IF(C39="","",INDEX(Giorni!$M$2:$M$367,C39-Giorni!$A$2+1)) -> 0 | N39: =IF(D39="","",INDEX(Giorni!$M$2:$M$367,D39-Giorni!$A$2+1)) -> 0 | O39: =IF(E39="","",INDEX(Giorni!$M$2:$M$367,E39-Giorni!$A$2+1)) -> 0 | P39: =IF(F39="","",INDEX(Giorni!$M$2:$M$367,F39-Giorni!$A$2+1)) -> 1 | Q39: =IF(G39="","",INDEX(Giorni!$M$2:$M$367,G39-Giorni!$A$2+1)) -> 1
A41: =IF(MONTH($J$29-WEEKDAY($J$29,2)+36)=MONTH($J$29),$J$29-WEEKDAY($J$29,2)+36,"") -> 46356 | B41: =IF(MONTH($J$29-WEEKDAY($J$29,2)+37)=MONTH($J$29),$J$29-WEEKDAY($J$29,2)+37,"") | C41: =IF(MONTH($J$29-WEEKDAY($J$29,2)+38)=MONTH($J$29),$J$29-WEEKDAY($J$29,2)+38,"") | D41: =IF(MONTH($J$29-WEEKDAY($J$29,2)+39)=MONTH($J$29),$J$29-WEEKDAY($J$29,2)+39,"") | E41: =IF(MONTH($J$29-WEEKDAY($J$29,2)+40)=MONTH($J$29),$J$29-WEEKDAY($J$29,2)+40,"") | F41: =IF(MONTH($J$29-WEEKDAY($J$29,2)+41)=MONTH($J$29),$J$29-WEEKDAY($J$29,2)+41,"") | G41: =IF(MONTH($J$29-WEEKDAY($J$29,2)+42)=MONTH($J$29),$J$29-WEEKDAY($J$29,2)+42,"") | K41: =IF(A41="","",INDEX(Giorni!$M$2:$M$367,A41-Giorni!$A$2+1)) -> 0 | L41: =IF(B41="","",INDEX(Giorni!$M$2:$M$367,B41-Giorni!$A$2+1)) | M41: =IF(C41="","",INDEX(Giorni!$M$2:$M$367,C41-Giorni!$A$2+1)) | N41: =IF(D41="","",INDEX(Giorni!$M$2:$M$367,D41-Giorni!$A$2+1)) | O41: =IF(E41="","",INDEX(Giorni!$M$2:$M$367,E41-Giorni!$A$2+1)) | P41: =IF(F41="","",INDEX(Giorni!$M$2:$M$367,F41-Giorni!$A$2+1)) | Q41: =IF(G41="","",INDEX(Giorni!$M$2:$M$367,G41-Giorni!$A$2+1))
A44: =CHOOSE(MONTH($J44),"GENNAIO","FEBBRAIO","MARZO","APRILE","MAGGIO","GIUGNO","LUGLIO","AGOSTO","SETTEMBRE","OTTOBRE","NOVEMBRE","DICEMBRE")&" "&YEAR($J44) -> DICEMBRE 2026 | J44: =EDATE(J29,1) -> 46357
A45: L | B45: M | C45: M | D45: G | E45: V | F45: S | G45: D
A46: =IF(MONTH($J$44-WEEKDAY($J$44,2)+1)=MONTH($J$44),$J$44-WEEKDAY($J$44,2)+1,"") | B46: =IF(MONTH($J$44-WEEKDAY($J$44,2)+2)=MONTH($J$44),$J$44-WEEKDAY($J$44,2)+2,"") -> 46357 | C46: =IF(MONTH($J$44-WEEKDAY($J$44,2)+3)=MONTH($J$44),$J$44-WEEKDAY($J$44,2)+3,"") -> 46358 | D46: =IF(MONTH($J$44-WEEKDAY($J$44,2)+4)=MONTH($J$44),$J$44-WEEKDAY($J$44,2)+4,"") -> 46359 | E46: =IF(MONTH($J$44-WEEKDAY($J$44,2)+5)=MONTH($J$44),$J$44-WEEKDAY($J$44,2)+5,"") -> 46360 | F46: =IF(MONTH($J$44-WEEKDAY($J$44,2)+6)=MONTH($J$44),$J$44-WEEKDAY($J$44,2)+6,"") -> 46361 | G46: =IF(MONTH($J$44-WEEKDAY($J$44,2)+7)=MONTH($J$44),$J$44-WEEKDAY($J$44,2)+7,"") -> 46362 | K46: =IF(A46="","",INDEX(Giorni!$M$2:$M$367,A46-Giorni!$A$2+1)) | L46: =IF(B46="","",INDEX(Giorni!$M$2:$M$367,B46-Giorni!$A$2+1)) -> 0 | M46: =IF(C46="","",INDEX(Giorni!$M$2:$M$367,C46-Giorni!$A$2+1)) -> 0 | N46: =IF(D46="","",INDEX(Giorni!$M$2:$M$367,D46-Giorni!$A$2+1)) -> 0 | O46: =IF(E46="","",INDEX(Giorni!$M$2:$M$367,E46-Giorni!$A$2+1)) -> 0 | P46: =IF(F46="","",INDEX(Giorni!$M$2:$M$367,F46-Giorni!$A$2+1)) -> 1 | Q46: =IF(G46="","",INDEX(Giorni!$M$2:$M$367,G46-Giorni!$A$2+1)) -> 1
A48: =IF(MONTH($J$44-WEEKDAY($J$44,2)+8)=MONTH($J$44),$J$44-WEEKDAY($J$44,2)+8,"") -> 46363 | B48: =IF(MONTH($J$44-WEEKDAY($J$44,2)+9)=MONTH($J$44),$J$44-WEEKDAY($J$44,2)+9,"") -> 46364 | C48: =IF(MONTH($J$44-WEEKDAY($J$44,2)+10)=MONTH($J$44),$J$44-WEEKDAY($J$44,2)+10,"") -> 46365 | D48: =IF(MONTH($J$44-WEEKDAY($J$44,2)+11)=MONTH($J$44),$J$44-WEEKDAY($J$44,2)+11,"") -> 46366 | E48: =IF(MONTH($J$44-WEEKDAY($J$44,2)+12)=MONTH($J$44),$J$44-WEEKDAY($J$44,2)+12,"") -> 46367 | F48: =IF(MONTH($J$44-WEEKDAY($J$44,2)+13)=MONTH($J$44),$J$44-WEEKDAY($J$44,2)+13,"") -> 46368 | G48: =IF(MONTH($J$44-WEEKDAY($J$44,2)+14)=MONTH($J$44),$J$44-WEEKDAY($J$44,2)+14,"") -> 46369 | K48: =IF(A48="","",INDEX(Giorni!$M$2:$M$367,A48-Giorni!$A$2+1)) -> 0 | L48: =IF(B48="","",INDEX(Giorni!$M$2:$M$367,B48-Giorni!$A$2+1)) -> 2 | M48: =IF(C48="","",INDEX(Giorni!$M$2:$M$367,C48-Giorni!$A$2+1)) -> 0 | N48: =IF(D48="","",INDEX(Giorni!$M$2:$M$367,D48-Giorni!$A$2+1)) -> 0 | O48: =IF(E48="","",INDEX(Giorni!$M$2:$M$367,E48-Giorni!$A$2+1)) -> 0 | P48: =IF(F48="","",INDEX(Giorni!$M$2:$M$367,F48-Giorni!$A$2+1)) -> 1 | Q48: =IF(G48="","",INDEX(Giorni!$M$2:$M$367,G48-Giorni!$A$2+1)) -> 1
A50: =IF(MONTH($J$44-WEEKDAY($J$44,2)+15)=MONTH($J$44),$J$44-WEEKDAY($J$44,2)+15,"") -> 46370 | B50: =IF(MONTH($J$44-WEEKDAY($J$44,2)+16)=MONTH($J$44),$J$44-WEEKDAY($J$44,2)+16,"") -> 46371 | C50: =IF(MONTH($J$44-WEEKDAY($J$44,2)+17)=MONTH($J$44),$J$44-WEEKDAY($J$44,2)+17,"") -> 46372 | D50: =IF(MONTH($J$44-WEEKDAY($J$44,2)+18)=MONTH($J$44),$J$44-WEEKDAY($J$44,2)+18,"") -> 46373 | E50: =IF(MONTH($J$44-WEEKDAY($J$44,2)+19)=MONTH($J$44),$J$44-WEEKDAY($J$44,2)+19,"") -> 46374 | F50: =IF(MONTH($J$44-WEEKDAY($J$44,2)+20)=MONTH($J$44),$J$44-WEEKDAY($J$44,2)+20,"") -> 46375 | G50: =IF(MONTH($J$44-WEEKDAY($J$44,2)+21)=MONTH($J$44),$J$44-WEEKDAY($J$44,2)+21,"") -> 46376 | K50: =IF(A50="","",INDEX(Giorni!$M$2:$M$367,A50-Giorni!$A$2+1)) -> 0 | L50: =IF(B50="","",INDEX(Giorni!$M$2:$M$367,B50-Giorni!$A$2+1)) -> 0 | M50: =IF(C50="","",INDEX(Giorni!$M$2:$M$367,C50-Giorni!$A$2+1)) -> 0 | N50: =IF(D50="","",INDEX(Giorni!$M$2:$M$367,D50-Giorni!$A$2+1)) -> 0 | O50: =IF(E50="","",INDEX(Giorni!$M$2:$M$367,E50-Giorni!$A$2+1)) -> 0 | P50: =IF(F50="","",INDEX(Giorni!$M$2:$M$367,F50-Giorni!$A$2+1)) -> 1 | Q50: =IF(G50="","",INDEX(Giorni!$M$2:$M$367,G50-Giorni!$A$2+1)) -> 1
A52: =IF(MONTH($J$44-WEEKDAY($J$44,2)+22)=MONTH($J$44),$J$44-WEEKDAY($J$44,2)+22,"") -> 46377 | B52: =IF(MONTH($J$44-WEEKDAY($J$44,2)+23)=MONTH($J$44),$J$44-WEEKDAY($J$44,2)+23,"") -> 46378 | C52: =IF(MONTH($J$44-WEEKDAY($J$44,2)+24)=MONTH($J$44),$J$44-WEEKDAY($J$44,2)+24,"") -> 46379 | D52: =IF(MONTH($J$44-WEEKDAY($J$44,2)+25)=MONTH($J$44),$J$44-WEEKDAY($J$44,2)+25,"") -> 46380 | E52: =IF(MONTH($J$44-WEEKDAY($J$44,2)+26)=MONTH($J$44),$J$44-WEEKDAY($J$44,2)+26,"") -> 46381 | F52: =IF(MONTH($J$44-WEEKDAY($J$44,2)+27)=MONTH($J$44),$J$44-WEEKDAY($J$44,2)+27,"") -> 46382 | G52: =IF(MONTH($J$44-WEEKDAY($J$44,2)+28)=MONTH($J$44),$J$44-WEEKDAY($J$44,2)+28,"") -> 46383 | K52: =IF(A52="","",INDEX(Giorni!$M$2:$M$367,A52-Giorni!$A$2+1)) -> 0 | L52: =IF(B52="","",INDEX(Giorni!$M$2:$M$367,B52-Giorni!$A$2+1)) -> 0 | M52: =IF(C52="","",INDEX(Giorni!$M$2:$M$367,C52-Giorni!$A$2+1)) -> 2 | N52: =IF(D52="","",INDEX(Giorni!$M$2:$M$367,D52-Giorni!$A$2+1)) -> 2 | O52: =IF(E52="","",INDEX(Giorni!$M$2:$M$367,E52-Giorni!$A$2+1)) -> 2 | P52: =IF(F52="","",INDEX(Giorni!$M$2:$M$367,F52-Giorni!$A$2+1)) -> 2 | Q52: =IF(G52="","",INDEX(Giorni!$M$2:$M$367,G52-Giorni!$A$2+1)) -> 2
A54: =IF(MONTH($J$44-WEEKDAY($J$44,2)+29)=MONTH($J$44),$J$44-WEEKDAY($J$44,2)+29,"") -> 46384 | B54: =IF(MONTH($J$44-WEEKDAY($J$44,2)+30)=MONTH($J$44),$J$44-WEEKDAY($J$44,2)+30,"") -> 46385 | C54: =IF(MONTH($J$44-WEEKDAY($J$44,2)+31)=MONTH($J$44),$J$44-WEEKDAY($J$44,2)+31,"") -> 46386 | D54: =IF(MONTH($J$44-WEEKDAY($J$44,2)+32)=MONTH($J$44),$J$44-WEEKDAY($J$44,2)+32,"") -> 46387 | E54: =IF(MONTH($J$44-WEEKDAY($J$44,2)+33)=MONTH($J$44),$J$44-WEEKDAY($J$44,2)+33,"") | F54: =IF(MONTH($J$44-WEEKDAY($J$44,2)+34)=MONTH($J$44),$J$44-WEEKDAY($J$44,2)+34,"") | G54: =IF(MONTH($J$44-WEEKDAY($J$44,2)+35)=MONTH($J$44),$J$44-WEEKDAY($J$44,2)+35,"") | K54: =IF(A54="","",INDEX(Giorni!$M$2:$M$367,A54-Giorni!$A$2+1)) -> 2 | L54: =IF(B54="","",INDEX(Giorni!$M$2:$M$367,B54-Giorni!$A$2+1)) -> 2 | M54: =IF(C54="","",INDEX(Giorni!$M$2:$M$367,C54-Giorni!$A$2+1)) -> 2 | N54: =IF(D54="","",INDEX(Giorni!$M$2:$M$367,D54-Giorni!$A$2+1)) -> 2 | O54: =IF(E54="","",INDEX(Giorni!$M$2:$M$367,E54-Giorni!$A$2+1)) | P54: =IF(F54="","",INDEX(Giorni!$M$2:$M$367,F54-Giorni!$A$2+1)) | Q54: =IF(G54="","",INDEX(Giorni!$M$2:$M$367,G54-Giorni!$A$2+1))
A56: =IF(MONTH($J$44-WEEKDAY($J$44,2)+36)=MONTH($J$44),$J$44-WEEKDAY($J$44,2)+36,"") | B56: =IF(MONTH($J$44-WEEKDAY($J$44,2)+37)=MONTH($J$44),$J$44-WEEKDAY($J$44,2)+37,"") | C56: =IF(MONTH($J$44-WEEKDAY($J$44,2)+38)=MONTH($J$44),$J$44-WEEKDAY($J$44,2)+38,"") | D56: =IF(MONTH($J$44-WEEKDAY($J$44,2)+39)=MONTH($J$44),$J$44-WEEKDAY($J$44,2)+39,"") | E56: =IF(MONTH($J$44-WEEKDAY($J$44,2)+40)=MONTH($J$44),$J$44-WEEKDAY($J$44,2)+40,"") | F56: =IF(MONTH($J$44-WEEKDAY($J$44,2)+41)=MONTH($J$44),$J$44-WEEKDAY($J$44,2)+41,"") | G56: =IF(MONTH($J$44-WEEKDAY($J$44,2)+42)=MONTH($J$44),$J$44-WEEKDAY($J$44,2)+42,"") | K56: =IF(A56="","",INDEX(Giorni!$M$2:$M$367,A56-Giorni!$A$2+1)) | L56: =IF(B56="","",INDEX(Giorni!$M$2:$M$367,B56-Giorni!$A$2+1)) | M56: =IF(C56="","",INDEX(Giorni!$M$2:$M$367,C56-Giorni!$A$2+1)) | N56: =IF(D56="","",INDEX(Giorni!$M$2:$M$367,D56-Giorni!$A$2+1)) | O56: =IF(E56="","",INDEX(Giorni!$M$2:$M$367,E56-Giorni!$A$2+1)) | P56: =IF(F56="","",INDEX(Giorni!$M$2:$M$367,F56-Giorni!$A$2+1)) | Q56: =IF(G56="","",INDEX(Giorni!$M$2:$M$367,G56-Giorni!$A$2+1))
A59: =CHOOSE(MONTH($J59),"GENNAIO","FEBBRAIO","MARZO","APRILE","MAGGIO","GIUGNO","LUGLIO","AGOSTO","SETTEMBRE","OTTOBRE","NOVEMBRE","DICEMBRE")&" "&YEAR($J59) -> GENNAIO 2027 | J59: =EDATE(J44,1) -> 46388
A60: L | B60: M | C60: M | D60: G | E60: V | F60: S | G60: D
A61: =IF(MONTH($J$59-WEEKDAY($J$59,2)+1)=MONTH($J$59),$J$59-WEEKDAY($J$59,2)+1,"") | B61: =IF(MONTH($J$59-WEEKDAY($J$59,2)+2)=MONTH($J$59),$J$59-WEEKDAY($J$59,2)+2,"") | C61: =IF(MONTH($J$59-WEEKDAY($J$59,2)+3)=MONTH($J$59),$J$59-WEEKDAY($J$59,2)+3,"") | D61: =IF(MONTH($J$59-WEEKDAY($J$59,2)+4)=MONTH($J$59),$J$59-WEEKDAY($J$59,2)+4,"") | E61: =IF(MONTH($J$59-WEEKDAY($J$59,2)+5)=MONTH($J$59),$J$59-WEEKDAY($J$59,2)+5,"") -> 46388 | F61: =IF(MONTH($J$59-WEEKDAY($J$59,2)+6)=MONTH($J$59),$J$59-WEEKDAY($J$59,2)+6,"") -> 46389 | G61: =IF(MONTH($J$59-WEEKDAY($J$59,2)+7)=MONTH($J$59),$J$59-WEEKDAY($J$59,2)+7,"") -> 46390 | K61: =IF(A61="","",INDEX(Giorni!$M$2:$M$367,A61-Giorni!$A$2+1)) | L61: =IF(B61="","",INDEX(Giorni!$M$2:$M$367,B61-Giorni!$A$2+1)) | M61: =IF(C61="","",INDEX(Giorni!$M$2:$M$367,C61-Giorni!$A$2+1)) | N61: =IF(D61="","",INDEX(Giorni!$M$2:$M$367,D61-Giorni!$A$2+1)) | O61: =IF(E61="","",INDEX(Giorni!$M$2:$M$367,E61-Giorni!$A$2+1)) -> 2 | P61: =IF(F61="","",INDEX(Giorni!$M$2:$M$367,F61-Giorni!$A$2+1)) -> 2 | Q61: =IF(G61="","",INDEX(Giorni!$M$2:$M$367,G61-Giorni!$A$2+1)) -> 2
A63: =IF(MONTH($J$59-WEEKDAY($J$59,2)+8)=MONTH($J$59),$J$59-WEEKDAY($J$59,2)+8,"") -> 46391 | B63: =IF(MONTH($J$59-WEEKDAY($J$59,2)+9)=MONTH($J$59),$J$59-WEEKDAY($J$59,2)+9,"") -> 46392 | C63: =IF(MONTH($J$59-WEEKDAY($J$59,2)+10)=MONTH($J$59),$J$59-WEEKDAY($J$59,2)+10,"") -> 46393 | D63: =IF(MONTH($J$59-WEEKDAY($J$59,2)+11)=MONTH($J$59),$J$59-WEEKDAY($J$59,2)+11,"") -> 46394 | E63: =IF(MONTH($J$59-WEEKDAY($J$59,2)+12)=MONTH($J$59),$J$59-WEEKDAY($J$59,2)+12,"") -> 46395 | F63: =IF(MONTH($J$59-WEEKDAY($J$59,2)+13)=MONTH($J$59),$J$59-WEEKDAY($J$59,2)+13,"") -> 46396 | G63: =IF(MONTH($J$59-WEEKDAY($J$59,2)+14)=MONTH($J$59),$J$59-WEEKDAY($J$59,2)+14,"") -> 46397 | K63: =IF(A63="","",INDEX(Giorni!$M$2:$M$367,A63-Giorni!$A$2+1)) -> 2 | L63: =IF(B63="","",INDEX(Giorni!$M$2:$M$367,B63-Giorni!$A$2+1)) -> 2 | M63: =IF(C63="","",INDEX(Giorni!$M$2:$M$367,C63-Giorni!$A$2+1)) -> 2 | N63: =IF(D63="","",INDEX(Giorni!$M$2:$M$367,D63-Giorni!$A$2+1)) -> 0 | O63: =IF(E63="","",INDEX(Giorni!$M$2:$M$367,E63-Giorni!$A$2+1)) -> 0 | P63: =IF(F63="","",INDEX(Giorni!$M$2:$M$367,F63-Giorni!$A$2+1)) -> 1 | Q63: =IF(G63="","",INDEX(Giorni!$M$2:$M$367,G63-Giorni!$A$2+1)) -> 1
...

Sheet Riepilogo
A1: RIEPILOGO
A3: PERIODO E BASE DI CALCOLO
A4: Inizio periodo | B4: =Impostazioni!$B$4 -> 46296
A5: Fine periodo | B5: =Impostazioni!$B$5 -> 46660
A6: Data usata nei calcoli | B6: =Impostazioni!$B$8 -> 46298 | C6: Oggi, salvo data di riferimento in Impostazioni
A7: Giorni di calendario del periodo | B7: =B5-B4+1 -> 365
A8: Giorni esclusi (festività e chiusure) | B8: =B7-B9 -> 53 | C8: Unione senza doppi conteggi
A9: Giorni validi (base del 56%) | B9: =SUM(Giorni!$F$2:$F$367) -> 312 | C9: Weekend inclusi
A10: Soglia minima di presenza | B10: =Impostazioni!$B$6 -> 0.56
A11: Presenze minime richieste | B11: =ROUNDUP(ROUND(B10*B9,6),0) -> 175 | C11: Arrotondato per eccesso
A12: Assenze massime consentite | B12: =B9-B11 -> 137
A14: STATO ATTUALE
A15: Assenze usate (non giustificate) | B15: =SUM(Giorni!$J$2:$J$367) -> 0
A16: Assenze giustificate (valgono come presenza) | B16: =SUM(Giorni!$K$2:$K$367) -> 0 | C16: Non riducono le assenze rimanenti
A17: ASSENZE RIMANENTI TOTALI | B17: =B12-B15 -> 137 | C17: Negativo = soglia superata
A18: Giorni validi rimanenti (da oggi incluso) | B18: =SUM(Giorni!$L$2:$L$367) -> 310
A19: Giorni validi trascorsi | B19: =B9-B18 -> 2
A20: Assenze usate nei giorni trascorsi | B20: =SUMIFS(Giorni!$J$2:$J$367,Giorni!$A$2:$A$367,"<"&B6) -> 0
A21: Presenze finora | B21: =B19-B20 -> 2 | C21: Ogni giorno valido trascorso senza assenza
A22: % presenza finora | B22: =IF(B19=0,"-",B21/B19) -> 1 | C22: Sui giorni validi trascorsi
A23: Presenze a fine periodo (se da oggi sempre presente) | B23: =B9-B15 -> 312 | C23: Da confrontare con le presenze minime
A24: % presenza a fine periodo (se da oggi sempre presente) | B24: =IF(B9=0,0,B23/B9) -> 1 | C24: Da confrontare con la soglia
A25: Margine sulla soglia (punti percentuali) | B25: =B24-B10 -> 0.44 | C25: Positivo = sopra la soglia
A27: PROIEZIONE MENSILE
A28: Mesi rimanenti (con frazioni) | B28: =Mesi!G17 -> 10.935484 | C28: Frazione del mese corrente + mesi interi successivi
A29: ASSENZE MENSILI RIMANENTI | B29: =IF(B28=0,0,ROUND(MAX(0,B17)/B28,4)) -> 12.528 | C29: Assenze rimanenti ÷ mesi rimanenti
A30: Base della frazione di mese | B30: =Impostazioni!$B$9 -> Giorni validi | C30: Modificabile in Impostazioni

Sheet Mesi
A1: DETTAGLIO MENSILE
A2: Presenze = giorni validi − assenze (le giustificate valgono come presenza). Peso residuo = parte del mese ancora da vivere (serve per la proiezione mensile).
A4: Mese | B4: Giorni validi | C4: Assenze | D4: Giustificate | E4: Presenze | F4: % presenza | G4: Peso residuo
A5: =CHOOSE(MONTH(H5),"Gennaio","Febbraio","Marzo","Aprile","Maggio","Giugno","Luglio","Agosto","Settembre","Ottobre","Novembre","Dicembre")&" "&YEAR(H5) -> Ottobre 2026 | B5: =SUMIFS(Giorni!$F$2:$F$367,Giorni!$B$2:$B$367,H5) -> 31 | C5: =SUMIFS(Giorni!$J$2:$J$367,Giorni!$B$2:$B$367,H5) -> 0 | D5: =SUMIFS(Giorni!$K$2:$K$367,Giorni!$B$2:$B$367,H5) -> 0 | E5: =B5-C5 -> 31 | F5: =IF(B5=0,"-",E5/B5) -> 1 | G5: =IF(B5=0,0,IF(Impostazioni!$B$9="Giorni di calendario",MAX(0,MIN(EOMONTH(H5,0),Impostazioni!$B$5)-MAX(H5,Impostazioni!$B$8,Impostazioni!$B$4)+1)/DAY(EOMONTH(H5,0)),SUMIFS(Giorni!$L$2:$L$367,Giorni!$B$2:$B$367,H5)/B5)) -> 0.93548387 | H5: =Impostazioni!$B$11 -> 46296
A6: =CHOOSE(MONTH(H6),"Gennaio","Febbraio","Marzo","Aprile","Maggio","Giugno","Luglio","Agosto","Settembre","Ottobre","Novembre","Dicembre")&" "&YEAR(H6) -> Novembre 2026 | B6: =SUMIFS(Giorni!$F$2:$F$367,Giorni!$B$2:$B$367,H6) -> 29 | C6: =SUMIFS(Giorni!$J$2:$J$367,Giorni!$B$2:$B$367,H6) -> 0 | D6: =SUMIFS(Giorni!$K$2:$K$367,Giorni!$B$2:$B$367,H6) -> 0 | E6: =B6-C6 -> 29 | F6: =IF(B6=0,"-",E6/B6) -> 1 | G6: =IF(B6=0,0,IF(Impostazioni!$B$9="Giorni di calendario",MAX(0,MIN(EOMONTH(H6,0),Impostazioni!$B$5)-MAX(H6,Impostazioni!$B$8,Impostazioni!$B$4)+1)/DAY(EOMONTH(H6,0)),SUMIFS(Giorni!$L$2:$L$367,Giorni!$B$2:$B$367,H6)/B6)) -> 1 | H6: =EDATE(H5,1) -> 46327
A7: =CHOOSE(MONTH(H7),"Gennaio","Febbraio","Marzo","Aprile","Maggio","Giugno","Luglio","Agosto","Settembre","Ottobre","Novembre","Dicembre")&" "&YEAR(H7) -> Dicembre 2026 | B7: =SUMIFS(Giorni!$F$2:$F$367,Giorni!$B$2:$B$367,H7) -> 21 | C7: =SUMIFS(Giorni!$J$2:$J$367,Giorni!$B$2:$B$367,H7) -> 0 | D7: =SUMIFS(Giorni!$K$2:$K$367,Giorni!$B$2:$B$367,H7) -> 0 | E7: =B7-C7 -> 21 | F7: =IF(B7=0,"-",E7/B7) -> 1 | G7: =IF(B7=0,0,IF(Impostazioni!$B$9="Giorni di calendario",MAX(0,MIN(EOMONTH(H7,0),Impostazioni!$B$5)-MAX(H7,Impostazioni!$B$8,Impostazioni!$B$4)+1)/DAY(EOMONTH(H7,0)),SUMIFS(Giorni!$L$2:$L$367,Giorni!$B$2:$B$367,H7)/B7)) -> 1 | H7: =EDATE(H6,1) -> 46357
A8: =CHOOSE(MONTH(H8),"Gennaio","Febbraio","Marzo","Aprile","Maggio","Giugno","Luglio","Agosto","Settembre","Ottobre","Novembre","Dicembre")&" "&YEAR(H8) -> Gennaio 2027 | B8: =SUMIFS(Giorni!$F$2:$F$367,Giorni!$B$2:$B$367,H8) -> 25 | C8: =SUMIFS(Giorni!$J$2:$J$367,Giorni!$B$2:$B$367,H8) -> 0 | D8: =SUMIFS(Giorni!$K$2:$K$367,Giorni!$B$2:$B$367,H8) -> 0 | E8: =B8-C8 -> 25 | F8: =IF(B8=0,"-",E8/B8) -> 1 | G8: =IF(B8=0,0,IF(Impostazioni!$B$9="Giorni di calendario",MAX(0,MIN(EOMONTH(H8,0),Impostazioni!$B$5)-MAX(H8,Impostazioni!$B$8,Impostazioni!$B$4)+1)/DAY(EOMONTH(H8,0)),SUMIFS(Giorni!$L$2:$L$367,Giorni!$B$2:$B$367,H8)/B8)) -> 1 | H8: =EDATE(H7,1) -> 46388
A9: =CHOOSE(MONTH(H9),"Gennaio","Febbraio","Marzo","Aprile","Maggio","Giugno","Luglio","Agosto","Settembre","Ottobre","Novembre","Dicembre")&" "&YEAR(H9) -> Febbraio 2027 | B9: =SUMIFS(Giorni!$F$2:$F$367,Giorni!$B$2:$B$367,H9) -> 28 | C9: =SUMIFS(Giorni!$J$2:$J$367,Giorni!$B$2:$B$367,H9) -> 0 | D9: =SUMIFS(Giorni!$K$2:$K$367,Giorni!$B$2:$B$367,H9) -> 0 | E9: =B9-C9 -> 28 | F9: =IF(B9=0,"-",E9/B9) -> 1 | G9: =IF(B9=0,0,IF(Impostazioni!$B$9="Giorni di calendario",MAX(0,MIN(EOMONTH(H9,0),Impostazioni!$B$5)-MAX(H9,Impostazioni!$B$8,Impostazioni!$B$4)+1)/DAY(EOMONTH(H9,0)),SUMIFS(Giorni!$L$2:$L$367,Giorni!$B$2:$B$367,H9)/B9)) -> 1 | H9: =EDATE(H8,1) -> 46419
A10: =CHOOSE(MONTH(H10),"Gennaio","Febbraio","Marzo","Aprile","Maggio","Giugno","Luglio","Agosto","Settembre","Ottobre","Novembre","Dicembre")&" "&YEAR(H10) -> Marzo 2027 | B10: =SUMIFS(Giorni!$F$2:$F$367,Giorni!$B$2:$B$367,H10) -> 29 | C10: =SUMIFS(Giorni!$J$2:$J$367,Giorni!$B$2:$B$367,H10) -> 0 | D10: =SUMIFS(Giorni!$K$2:$K$367,Giorni!$B$2:$B$367,H10) -> 0 | E10: =B10-C10 -> 29 | F10: =IF(B10=0,"-",E10/B10) -> 1 | G10: =IF(B10=0,0,IF(Impostazioni!$B$9="Giorni di calendario",MAX(0,MIN(EOMONTH(H10,0),Impostazioni!$B$5)-MAX(H10,Impostazioni!$B$8,Impostazioni!$B$4)+1)/DAY(EOMONTH(H10,0)),SUMIFS(Giorni!$L$2:$L$367,Giorni!$B$2:$B$367,H10)/B10)) -> 1 | H10: =EDATE(H9,1) -> 46447
A11: =CHOOSE(MONTH(H11),"Gennaio","Febbraio","Marzo","Aprile","Maggio","Giugno","Luglio","Agosto","Settembre","Ottobre","Novembre","Dicembre")&" "&YEAR(H11) -> Aprile 2027 | B11: =SUMIFS(Giorni!$F$2:$F$367,Giorni!$B$2:$B$367,H11) -> 29 | C11: =SUMIFS(Giorni!$J$2:$J$367,Giorni!$B$2:$B$367,H11) -> 0 | D11: =SUMIFS(Giorni!$K$2:$K$367,Giorni!$B$2:$B$367,H11) -> 0 | E11: =B11-C11 -> 29 | F11: =IF(B11=0,"-",E11/B11) -> 1 | G11: =IF(B11=0,0,IF(Impostazioni!$B$9="Giorni di calendario",MAX(0,MIN(EOMONTH(H11,0),Impostazioni!$B$5)-MAX(H11,Impostazioni!$B$8,Impostazioni!$B$4)+1)/DAY(EOMONTH(H11,0)),SUMIFS(Giorni!$L$2:$L$367,Giorni!$B$2:$B$367,H11)/B11)) -> 1 | H11: =EDATE(H10,1) -> 46478
A12: =CHOOSE(MONTH(H12),"Gennaio","Febbraio","Marzo","Aprile","Maggio","Giugno","Luglio","Agosto","Settembre","Ottobre","Novembre","Dicembre")&" "&YEAR(H12) -> Maggio 2027 | B12: =SUMIFS(Giorni!$F$2:$F$367,Giorni!$B$2:$B$367,H12) -> 30 | C12: =SUMIFS(Giorni!$J$2:$J$367,Giorni!$B$2:$B$367,H12) -> 0 | D12: =SUMIFS(Giorni!$K$2:$K$367,Giorni!$B$2:$B$367,H12) -> 0 | E12: =B12-C12 -> 30 | F12: =IF(B12=0,"-",E12/B12) -> 1 | G12: =IF(B12=0,0,IF(Impostazioni!$B$9="Giorni di calendario",MAX(0,MIN(EOMONTH(H12,0),Impostazioni!$B$5)-MAX(H12,Impostazioni!$B$8,Impostazioni!$B$4)+1)/DAY(EOMONTH(H12,0)),SUMIFS(Giorni!$L$2:$L$367,Giorni!$B$2:$B$367,H12)/B12)) -> 1 | H12: =EDATE(H11,1) -> 46508
A13: =CHOOSE(MONTH(H13),"Gennaio","Febbraio","Marzo","Aprile","Maggio","Giugno","Luglio","Agosto","Settembre","Ottobre","Novembre","Dicembre")&" "&YEAR(H13) -> Giugno 2027 | B13: =SUMIFS(Giorni!$F$2:$F$367,Giorni!$B$2:$B$367,H13) -> 29 | C13: =SUMIFS(Giorni!$J$2:$J$367,Giorni!$B$2:$B$367,H13) -> 0 | D13: =SUMIFS(Giorni!$K$2:$K$367,Giorni!$B$2:$B$367,H13) -> 0 | E13: =B13-C13 -> 29 | F13: =IF(B13=0,"-",E13/B13) -> 1 | G13: =IF(B13=0,0,IF(Impostazioni!$B$9="Giorni di calendario",MAX(0,MIN(EOMONTH(H13,0),Impostazioni!$B$5)-MAX(H13,Impostazioni!$B$8,Impostazioni!$B$4)+1)/DAY(EOMONTH(H13,0)),SUMIFS(Giorni!$L$2:$L$367,Giorni!$B$2:$B$367,H13)/B13)) -> 1 | H13: =EDATE(H12,1) -> 46539
A14: =CHOOSE(MONTH(H14),"Gennaio","Febbraio","Marzo","Aprile","Maggio","Giugno","Luglio","Agosto","Settembre","Ottobre","Novembre","Dicembre")&" "&YEAR(H14) -> Luglio 2027 | B14: =SUMIFS(Giorni!$F$2:$F$367,Giorni!$B$2:$B$367,H14) -> 31 | C14: =SUMIFS(Giorni!$J$2:$J$367,Giorni!$B$2:$B$367,H14) -> 0 | D14: =SUMIFS(Giorni!$K$2:$K$367,Giorni!$B$2:$B$367,H14) -> 0 | E14: =B14-C14 -> 31 | F14: =IF(B14=0,"-",E14/B14) -> 1 | G14: =IF(B14=0,0,IF(Impostazioni!$B$9="Giorni di calendario",MAX(0,MIN(EOMONTH(H14,0),Impostazioni!$B$5)-MAX(H14,Impostazioni!$B$8,Impostazioni!$B$4)+1)/DAY(EOMONTH(H14,0)),SUMIFS(Giorni!$L$2:$L$367,Giorni!$B$2:$B$367,H14)/B14)) -> 1 | H14: =EDATE(H13,1) -> 46569
A15: =CHOOSE(MONTH(H15),"Gennaio","Febbraio","Marzo","Aprile","Maggio","Giugno","Luglio","Agosto","Settembre","Ottobre","Novembre","Dicembre")&" "&YEAR(H15) -> Agosto 2027 | B15: =SUMIFS(Giorni!$F$2:$F$367,Giorni!$B$2:$B$367,H15) -> 0 | C15: =SUMIFS(Giorni!$J$2:$J$367,Giorni!$B$2:$B$367,H15) -> 0 | D15: =SUMIFS(Giorni!$K$2:$K$367,Giorni!$B$2:$B$367,H15) -> 0 | E15: =B15-C15 -> 0 | F15: =IF(B15=0,"-",E15/B15) -> - | G15: =IF(B15=0,0,IF(Impostazioni!$B$9="Giorni di calendario",MAX(0,MIN(EOMONTH(H15,0),Impostazioni!$B$5)-MAX(H15,Impostazioni!$B$8,Impostazioni!$B$4)+1)/DAY(EOMONTH(H15,0)),SUMIFS(Giorni!$L$2:$L$367,Giorni!$B$2:$B$367,H15)/B15)) -> 0 | H15: =EDATE(H14,1) -> 46600
A16: =CHOOSE(MONTH(H16),"Gennaio","Febbraio","Marzo","Aprile","Maggio","Giugno","Luglio","Agosto","Settembre","Ottobre","Novembre","Dicembre")&" "&YEAR(H16) -> Settembre 2027 | B16: =SUMIFS(Giorni!$F$2:$F$367,Giorni!$B$2:$B$367,H16) -> 30 | C16: =SUMIFS(Giorni!$J$2:$J$367,Giorni!$B$2:$B$367,H16) -> 0 | D16: =SUMIFS(Giorni!$K$2:$K$367,Giorni!$B$2:$B$367,H16) -> 0 | E16: =B16-C16 -> 30 | F16: =IF(B16=0,"-",E16/B16) -> 1 | G16: =IF(B16=0,0,IF(Impostazioni!$B$9="Giorni di calendario",MAX(0,MIN(EOMONTH(H16,0),Impostazioni!$B$5)-MAX(H16,Impostazioni!$B$8,Impostazioni!$B$4)+1)/DAY(EOMONTH(H16,0)),SUMIFS(Giorni!$L$2:$L$367,Giorni!$B$2:$B$367,H16)/B16)) -> 1 | H16: =EDATE(H15,1) -> 46631
A17: TOTALE | B17: =SUM(B5:B16) -> 312 | C17: =SUM(C5:C16) -> 0 | D17: =SUM(D5:D16) -> 0 | E17: =SUM(E5:E16) -> 312 | F17: =IF(B17=0,"-",E17/B17) -> 1 | G17: =SUM(G5:G16) -> 10.935484

Sheet Elenco
A1: ELENCO DELLE ASSENZE SEGNATE
A2: Compilato in automatico dal Calendario, in ordine di data: serve per confrontare le assenze con il registro del badge elettronico.
A3: ="Segnate: "&MAX(Giorni!$N$2:$N$367)&" · Contano come assenza: "&Riepilogo!B15&" · Giustificate valide: "&Riepilogo!B16 -> Segnate: 0 · Contano come assenza: 0 · Giustificate valide: 0
A4: N° | B4: Data | C4: Giorno | D4: Tipo | E4: Conta? | F4: Nota
A5: =IF(G5="","",1) | B5: =IF(G5="","",INDEX(Giorni!$A$2:$A$367,G5)) | C5: =IF(G5="","",CHOOSE(WEEKDAY(B5,2),"lunedì","martedì","mercoledì","giovedì","venerdì","sabato","domenica")) | D5: =IF(G5="","",IF(INDEX(Giorni!$I$2:$I$367,G5)="A","Assenza","Giustificata")) | E5: =IF(G5="","",IF(INDEX(Giorni!$F$2:$F$367,G5)=1,"Sì","No")) | F5: =IF(G5="","",IF(E5="Sì",IF(D5="Giustificata","Conta come presenza",""),IF(INDEX(Giorni!$D$2:$D$367,G5)=1,"Festività: non conta",IF(INDEX(Giorni!$E$2:$E$367,G5)=1,"Chiusura: non conta","Fuori periodo: non conta")))) | G5: =IFERROR(MATCH(1,Giorni!$N$2:$N$367,0),"")
A6: =IF(G6="","",2) | B6: =IF(G6="","",INDEX(Giorni!$A$2:$A$367,G6)) | C6: =IF(G6="","",CHOOSE(WEEKDAY(B6,2),"lunedì","martedì","mercoledì","giovedì","venerdì","sabato","domenica")) | D6: =IF(G6="","",IF(INDEX(Giorni!$I$2:$I$367,G6)="A","Assenza","Giustificata")) | E6: =IF(G6="","",IF(INDEX(Giorni!$F$2:$F$367,G6)=1,"Sì","No")) | F6: =IF(G6="","",IF(E6="Sì",IF(D6="Giustificata","Conta come presenza",""),IF(INDEX(Giorni!$D$2:$D$367,G6)=1,"Festività: non conta",IF(INDEX(Giorni!$E$2:$E$367,G6)=1,"Chiusura: non conta","Fuori periodo: non conta")))) | G6: =IFERROR(MATCH(2,Giorni!$N$2:$N$367,0),"")
A7: =IF(G7="","",3) | B7: =IF(G7="","",INDEX(Giorni!$A$2:$A$367,G7)) | C7: =IF(G7="","",CHOOSE(WEEKDAY(B7,2),"lunedì","martedì","mercoledì","giovedì","venerdì","sabato","domenica")) | D7: =IF(G7="","",IF(INDEX(Giorni!$I$2:$I$367,G7)="A","Assenza","Giustificata")) | E7: =IF(G7="","",IF(INDEX(Giorni!$F$2:$F$367,G7)=1,"Sì","No")) | F7: =IF(G7="","",IF(E7="Sì",IF(D7="Giustificata","Conta come presenza",""),IF(INDEX(Giorni!$D$2:$D$367,G7)=1,"Festività: non conta",IF(INDEX(Giorni!$E$2:$E$367,G7)=1,"Chiusura: non conta","Fuori periodo: non conta")))) | G7: =IFERROR(MATCH(3,Giorni!$N$2:$N$367,0),"")
A8: =IF(G8="","",4) | B8: =IF(G8="","",INDEX(Giorni!$A$2:$A$367,G8)) | C8: =IF(G8="","",CHOOSE(WEEKDAY(B8,2),"lunedì","martedì","mercoledì","giovedì","venerdì","sabato","domenica")) | D8: =IF(G8="","",IF(INDEX(Giorni!$I$2:$I$367,G8)="A","Assenza","Giustificata")) | E8: =IF(G8="","",IF(INDEX(Giorni!$F$2:$F$367,G8)=1,"Sì","No")) | F8: =IF(G8="","",IF(E8="Sì",IF(D8="Giustificata","Conta come presenza",""),IF(INDEX(Giorni!$D$2:$D$367,G8)=1,"Festività: non conta",IF(INDEX(Giorni!$E$2:$E$367,G8)=1,"Chiusura: non conta","Fuori periodo: non conta")))) | G8: =IFERROR(MATCH(4,Giorni!$N$2:$N$367,0),"")
A9: =IF(G9="","",5) | B9: =IF(G9="","",INDEX(Giorni!$A$2:$A$367,G9)) | C9: =IF(G9="","",CHOOSE(WEEKDAY(B9,2),"lunedì","martedì","mercoledì","giovedì","venerdì","sabato","domenica")) | D9: =IF(G9="","",IF(INDEX(Giorni!$I$2:$I$367,G9)="A","Assenza","Giustificata")) | E9: =IF(G9="","",IF(INDEX(Giorni!$F$2:$F$367,G9)=1,"Sì","No")) | F9: =IF(G9="","",IF(E9="Sì",IF(D9="Giustificata","Conta come presenza",""),IF(INDEX(Giorni!$D$2:$D$367,G9)=1,"Festività: non conta",IF(INDEX(Giorni!$E$2:$E$367,G9)=1,"Chiusura: non conta","Fuori periodo: non conta")))) | G9: =IFERROR(MATCH(5,Giorni!$N$2:$N$367,0),"")
A10: =IF(G10="","",6) | B10: =IF(G10="","",INDEX(Giorni!$A$2:$A$367,G10)) | C10: =IF(G10="","",CHOOSE(WEEKDAY(B10,2),"lunedì","martedì","mercoledì","giovedì","venerdì","sabato","domenica")) | D10: =IF(G10="","",IF(INDEX(Giorni!$I$2:$I$367,G10)="A","Assenza","Giustificata")) | E10: =IF(G10="","",IF(INDEX(Giorni!$F$2:$F$367,G10)=1,"Sì","No")) | F10: =IF(G10="","",IF(E10="Sì",IF(D10="Giustificata","Conta come presenza",""),IF(INDEX(Giorni!$D$2:$D$367,G10)=1,"Festività: non conta",IF(INDEX(Giorni!$E$2:$E$367,G10)=1,"Chiusura: non conta","Fuori periodo: non conta")))) | G10: =IFERROR(MATCH(6,Giorni!$N$2:$N$367,0),"")
A11: =IF(G11="","",7) | B11: =IF(G11="","",INDEX(Giorni!$A$2:$A$367,G11)) | C11: =IF(G11="","",CHOOSE(WEEKDAY(B11,2),"lunedì","martedì","mercoledì","giovedì","venerdì","sabato","domenica")) | D11: =IF(G11="","",IF(INDEX(Giorni!$I$2:$I$367,G11)="A","Assenza","Giustificata")) | E11: =IF(G11="","",IF(INDEX(Giorni!$F$2:$F$367,G11)=1,"Sì","No")) | F11: =IF(G11="","",IF(E11="Sì",IF(D11="Giustificata","Conta come presenza",""),IF(INDEX(Giorni!$D$2:$D$367,G11)=1,"Festività: non conta",IF(INDEX(Giorni!$E$2:$E$367,G11)=1,"Chiusura: non conta","Fuori periodo: non conta")))) | G11: =IFERROR(MATCH(7,Giorni!$N$2:$N$367,0),"")
A12: =IF(G12="","",8) | B12: =IF(G12="","",INDEX(Giorni!$A$2:$A$367,G12)) | C12: =IF(G12="","",CHOOSE(WEEKDAY(B12,2),"lunedì","martedì","mercoledì","giovedì","venerdì","sabato","domenica")) | D12: =IF(G12="","",IF(INDEX(Giorni!$I$2:$I$367,G12)="A","Assenza","Giustificata")) | E12: =IF(G12="","",IF(INDEX(Giorni!$F$2:$F$367,G12)=1,"Sì","No")) | F12: =IF(G12="","",IF(E12="Sì",IF(D12="Giustificata","Conta come presenza",""),IF(INDEX(Giorni!$D$2:$D$367,G12)=1,"Festività: non conta",IF(INDEX(Giorni!$E$2:$E$367,G12)=1,"Chiusura: non conta","Fuori periodo: non conta")))) | G12: =IFERROR(MATCH(8,Giorni!$N$2:$N$367,0),"")
A13: =IF(G13="","",9) | B13: =IF(G13="","",INDEX(Giorni!$A$2:$A$367,G13)) | C13: =IF(G13="","",CHOOSE(WEEKDAY(B13,2),"lunedì","martedì","mercoledì","giovedì","venerdì","sabato","domenica")) | D13: =IF(G13="","",IF(INDEX(Giorni!$I$2:$I$367,G13)="A","Assenza","Giustificata")) | E13: =IF(G13="","",IF(INDEX(Giorni!$F$2:$F$367,G13)=1,"Sì","No")) | F13: =IF(G13="","",IF(E13="Sì",IF(D13="Giustificata","Conta come presenza",""),IF(INDEX(Giorni!$D$2:$D$367,G13)=1,"Festività: non conta",IF(INDEX(Giorni!$E$2:$E$367,G13)=1,"Chiusura: non conta","Fuori periodo: non conta")))) | G13: =IFERROR(MATCH(9,Giorni!$N$2:$N$367,0),"")
A14: =IF(G14="","",10) | B14: =IF(G14="","",INDEX(Giorni!$A$2:$A$367,G14)) | C14: =IF(G14="","",CHOOSE(WEEKDAY(B14,2),"lunedì","martedì","mercoledì","giovedì","venerdì","sabato","domenica")) | D14: =IF(G14="","",IF(INDEX(Giorni!$I$2:$I$367,G14)="A","Assenza","Giustificata")) | E14: =IF(G14="","",IF(INDEX(Giorni!$F$2:$F$367,G14)=1,"Sì","No")) | F14: =IF(G14="","",IF(E14="Sì",IF(D14="Giustificata","Conta come presenza",""),IF(INDEX(Giorni!$D$2:$D$367,G14)=1,"Festività: non conta",IF(INDEX(Giorni!$E$2:$E$367,G14)=1,"Chiusura: non conta","Fuori periodo: non conta")))) | G14: =IFERROR(MATCH(10,Giorni!$N$2:$N$367,0),"")
A15: =IF(G15="","",11) | B15: =IF(G15="","",INDEX(Giorni!$A$2:$A$367,G15)) | C15: =IF(G15="","",CHOOSE(WEEKDAY(B15,2),"lunedì","martedì","mercoledì","giovedì","venerdì","sabato","domenica")) | D15: =IF(G15="","",IF(INDEX(Giorni!$I$2:$I$367,G15)="A","Assenza","Giustificata")) | E15: =IF(G15="","",IF(INDEX(Giorni!$F$2:$F$367,G15)=1,"Sì","No")) | F15: =IF(G15="","",IF(E15="Sì",IF(D15="Giustificata","Conta come presenza",""),IF(INDEX(Giorni!$D$2:$D$367,G15)=1,"Festività: non conta",IF(INDEX(Giorni!$E$2:$E$367,G15)=1,"Chiusura: non conta","Fuori periodo: non conta")))) | G15: =IFERROR(MATCH(11,Giorni!$N$2:$N$367,0),"")
A16: =IF(G16="","",12) | B16: =IF(G16="","",INDEX(Giorni!$A$2:$A$367,G16)) | C16: =IF(G16="","",CHOOSE(WEEKDAY(B16,2),"lunedì","martedì","mercoledì","giovedì","venerdì","sabato","domenica")) | D16: =IF(G16="","",IF(INDEX(Giorni!$I$2:$I$367,G16)="A","Assenza","Giustificata")) | E16: =IF(G16="","",IF(INDEX(Giorni!$F$2:$F$367,G16)=1,"Sì","No")) | F16: =IF(G16="","",IF(E16="Sì",IF(D16="Giustificata","Conta come presenza",""),IF(INDEX(Giorni!$D$2:$D$367,G16)=1,"Festività: non conta",IF(INDEX(Giorni!$E$2:$E$367,G16)=1,"Chiusura: non conta","Fuori periodo: non conta")))) | G16: =IFERROR(MATCH(12,Giorni!$N$2:$N$367,0),"")
A17: =IF(G17="","",13) | B17: =IF(G17="","",INDEX(Giorni!$A$2:$A$367,G17)) | C17: =IF(G17="","",CHOOSE(WEEKDAY(B17,2),"lunedì","martedì","mercoledì","giovedì","venerdì","sabato","domenica")) | D17: =IF(G17="","",IF(INDEX(Giorni!$I$2:$I$367,G17)="A","Assenza","Giustificata")) | E17: =IF(G17="","",IF(INDEX(Giorni!$F$2:$F$367,G17)=1,"Sì","No")) | F17: =IF(G17="","",IF(E17="Sì",IF(D17="Giustificata","Conta come presenza",""),IF(INDEX(Giorni!$D$2:$D$367,G17)=1,"Festività: non conta",IF(INDEX(Giorni!$E$2:$E$367,G17)=1,"Chiusura: non conta","Fuori periodo: non conta")))) | G17: =IFERROR(MATCH(13,Giorni!$N$2:$N$367,0),"")
A18: =IF(G18="","",14) | B18: =IF(G18="","",INDEX(Giorni!$A$2:$A$367,G18)) | C18: =IF(G18="","",CHOOSE(WEEKDAY(B18,2),"lunedì","martedì","mercoledì","giovedì","venerdì","sabato","domenica")) | D18: =IF(G18="","",IF(INDEX(Giorni!$I$2:$I$367,G18)="A","Assenza","Giustificata")) | E18: =IF(G18="","",IF(INDEX(Giorni!$F$2:$F$367,G18)=1,"Sì","No")) | F18: =IF(G18="","",IF(E18="Sì",IF(D18="Giustificata","Conta come presenza",""),IF(INDEX(Giorni!$D$2:$D$367,G18)=1,"Festività: non conta",IF(INDEX(Giorni!$E$2:$E$367,G18)=1,"Chiusura: non conta","Fuori periodo: non conta")))) | G18: =IFERROR(MATCH(14,Giorni!$N$2:$N$367,0),"")
A19: =IF(G19="","",15) | B19: =IF(G19="","",INDEX(Giorni!$A$2:$A$367,G19)) | C19: =IF(G19="","",CHOOSE(WEEKDAY(B19,2),"lunedì","martedì","mercoledì","giovedì","venerdì","sabato","domenica")) | D19: =IF(G19="","",IF(INDEX(Giorni!$I$2:$I$367,G19)="A","Assenza","Giustificata")) | E19: =IF(G19="","",IF(INDEX(Giorni!$F$2:$F$367,G19)=1,"Sì","No")) | F19: =IF(G19="","",IF(E19="Sì",IF(D19="Giustificata","Conta come presenza",""),IF(INDEX(Giorni!$D$2:$D$367,G19)=1,"Festività: non conta",IF(INDEX(Giorni!$E$2:$E$367,G19)=1,"Chiusura: non conta","Fuori periodo: non conta")))) | G19: =IFERROR(MATCH(15,Giorni!$N$2:$N$367,0),"")
A20: =IF(G20="","",16) | B20: =IF(G20="","",INDEX(Giorni!$A$2:$A$367,G20)) | C20: =IF(G20="","",CHOOSE(WEEKDAY(B20,2),"lunedì","martedì","mercoledì","giovedì","venerdì","sabato","domenica")) | D20: =IF(G20="","",IF(INDEX(Giorni!$I$2:$I$367,G20)="A","Assenza","Giustificata")) | E20: =IF(G20="","",IF(INDEX(Giorni!$F$2:$F$367,G20)=1,"Sì","No")) | F20: =IF(G20="","",IF(E20="Sì",IF(D20="Giustificata","Conta come presenza",""),IF(INDEX(Giorni!$D$2:$D$367,G20)=1,"Festività: non conta",IF(INDEX(Giorni!$E$2:$E$367,G20)=1,"Chiusura: non conta","Fuori periodo: non conta")))) | G20: =IFERROR(MATCH(16,Giorni!$N$2:$N$367,0),"")
A21: =IF(G21="","",17) | B21: =IF(G21="","",INDEX(Giorni!$A$2:$A$367,G21)) | C21: =IF(G21="","",CHOOSE(WEEKDAY(B21,2),"lunedì","martedì","mercoledì","giovedì","venerdì","sabato","domenica")) | D21: =IF(G21="","",IF(INDEX(Giorni!$I$2:$I$367,G21)="A","Assenza","Giustificata")) | E21: =IF(G21="","",IF(INDEX(Giorni!$F$2:$F$367,G21)=1,"Sì","No")) | F21: =IF(G21="","",IF(E21="Sì",IF(D21="Giustificata","Conta come presenza",""),IF(INDEX(Giorni!$D$2:$D$367,G21)=1,"Festività: non conta",IF(INDEX(Giorni!$E$2:$E$367,G21)=1,"Chiusura: non conta","Fuori periodo: non conta")))) | G21: =IFERROR(MATCH(17,Giorni!$N$2:$N$367,0),"")
A22: =IF(G22="","",18) | B22: =IF(G22="","",INDEX(Giorni!$A$2:$A$367,G22)) | C22: =IF(G22="","",CHOOSE(WEEKDAY(B22,2),"lunedì","martedì","mercoledì","giovedì","venerdì","sabato","domenica")) | D22: =IF(G22="","",IF(INDEX(Giorni!$I$2:$I$367,G22)="A","Assenza","Giustificata")) | E22: =IF(G22="","",IF(INDEX(Giorni!$F$2:$F$367,G22)=1,"Sì","No")) | F22: =IF(G22="","",IF(E22="Sì",IF(D22="Giustificata","Conta come presenza",""),IF(INDEX(Giorni!$D$2:$D$367,G22)=1,"Festività: non conta",IF(INDEX(Giorni!$E$2:$E$367,G22)=1,"Chiusura: non conta","Fuori periodo: non conta")))) | G22: =IFERROR(MATCH(18,Giorni!$N$2:$N$367,0),"")
A23: =IF(G23="","",19) | B23: =IF(G23="","",INDEX(Giorni!$A$2:$A$367,G23)) | C23: =IF(G23="","",CHOOSE(WEEKDAY(B23,2),"lunedì","martedì","mercoledì","giovedì","venerdì","sabato","domenica")) | D23: =IF(G23="","",IF(INDEX(Giorni!$I$2:$I$367,G23)="A","Assenza","Giustificata")) | E23: =IF(G23="","",IF(INDEX(Giorni!$F$2:$F$367,G23)=1,"Sì","No")) | F23: =IF(G23="","",IF(E23="Sì",IF(D23="Giustificata","Conta come presenza",""),IF(INDEX(Giorni!$D$2:$D$367,G23)=1,"Festività: non conta",IF(INDEX(Giorni!$E$2:$E$367,G23)=1,"Chiusura: non conta","Fuori periodo: non conta")))) | G23: =IFERROR(MATCH(19,Giorni!$N$2:$N$367,0),"")
A24: =IF(G24="","",20) | B24: =IF(G24="","",INDEX(Giorni!$A$2:$A$367,G24)) | C24: =IF(G24="","",CHOOSE(WEEKDAY(B24,2),"lunedì","martedì","mercoledì","giovedì","venerdì","sabato","domenica")) | D24: =IF(G24="","",IF(INDEX(Giorni!$I$2:$I$367,G24)="A","Assenza","Giustificata")) | E24: =IF(G24="","",IF(INDEX(Giorni!$F$2:$F$367,G24)=1,"Sì","No")) | F24: =IF(G24="","",IF(E24="Sì",IF(D24="Giustificata","Conta come presenza",""),IF(INDEX(Giorni!$D$2:$D$367,G24)=1,"Festività: non conta",IF(INDEX(Giorni!$E$2:$E$367,G24)=1,"Chiusura: non conta","Fuori periodo: non conta")))) | G24: =IFERROR(MATCH(20,Giorni!$N$2:$N$367,0),"")
A25: =IF(G25="","",21) | B25: =IF(G25="","",INDEX(Giorni!$A$2:$A$367,G25)) | C25: =IF(G25="","",CHOOSE(WEEKDAY(B25,2),"lunedì","martedì","mercoledì","giovedì","venerdì","sabato","domenica")) | D25: =IF(G25="","",IF(INDEX(Giorni!$I$2:$I$367,G25)="A","Assenza","Giustificata")) | E25: =IF(G25="","",IF(INDEX(Giorni!$F$2:$F$367,G25)=1,"Sì","No")) | F25: =IF(G25="","",IF(E25="Sì",IF(D25="Giustificata","Conta come presenza",""),IF(INDEX(Giorni!$D$2:$D$367,G25)=1,"Festività: non conta",IF(INDEX(Giorni!$E$2:$E$367,G25)=1,"Chiusura: non conta","Fuori periodo: non conta")))) | G25: =IFERROR(MATCH(21,Giorni!$N$2:$N$367,0),"")
A26: =IF(G26="","",22) | B26: =IF(G26="","",INDEX(Giorni!$A$2:$A$367,G26)) | C26: =IF(G26="","",CHOOSE(WEEKDAY(B26,2),"lunedì","martedì","mercoledì","giovedì","venerdì","sabato","domenica")) | D26: =IF(G26="","",IF(INDEX(Giorni!$I$2:$I$367,G26)="A","Assenza","Giustificata")) | E26: =IF(G26="","",IF(INDEX(Giorni!$F$2:$F$367,G26)=1,"Sì","No")) | F26: =IF(G26="","",IF(E26="Sì",IF(D26="Giustificata","Conta come presenza",""),IF(INDEX(Giorni!$D$2:$D$367,G26)=1,"Festività: non conta",IF(INDEX(Giorni!$E$2:$E$367,G26)=1,"Chiusura: non conta","Fuori periodo: non conta")))) | G26: =IFERROR(MATCH(22,Giorni!$N$2:$N$367,0),"")
A27: =IF(G27="","",23) | B27: =IF(G27="","",INDEX(Giorni!$A$2:$A$367,G27)) | C27: =IF(G27="","",CHOOSE(WEEKDAY(B27,2),"lunedì","martedì","mercoledì","giovedì","venerdì","sabato","domenica")) | D27: =IF(G27="","",IF(INDEX(Giorni!$I$2:$I$367,G27)="A","Assenza","Giustificata")) | E27: =IF(G27="","",IF(INDEX(Giorni!$F$2:$F$367,G27)=1,"Sì","No")) | F27: =IF(G27="","",IF(E27="Sì",IF(D27="Giustificata","Conta come presenza",""),IF(INDEX(Giorni!$D$2:$D$367,G27)=1,"Festività: non conta",IF(INDEX(Giorni!$E$2:$E$367,G27)=1,"Chiusura: non conta","Fuori periodo: non conta")))) | G27: =IFERROR(MATCH(23,Giorni!$N$2:$N$367,0),"")
A28: =IF(G28="","",24) | B28: =IF(G28="","",INDEX(Giorni!$A$2:$A$367,G28)) | C28: =IF(G28="","",CHOOSE(WEEKDAY(B28,2),"lunedì","martedì","mercoledì","giovedì","venerdì","sabato","domenica")) | D28: =IF(G28="","",IF(INDEX(Giorni!$I$2:$I$367,G28)="A","Assenza","Giustificata")) | E28: =IF(G28="","",IF(INDEX(Giorni!$F$2:$F$367,G28)=1,"Sì","No")) | F28: =IF(G28="","",IF(E28="Sì",IF(D28="Giustificata","Conta come presenza",""),IF(INDEX(Giorni!$D$2:$D$367,G28)=1,"Festività: non conta",IF(INDEX(Giorni!$E$2:$E$367,G28)=1,"Chiusura: non conta","Fuori periodo: non conta")))) | G28: =IFERROR(MATCH(24,Giorni!$N$2:$N$367,0),"")
A29: =IF(G29="","",25) | B29: =IF(G29="","",INDEX(Giorni!$A$2:$A$367,G29)) | C29: =IF(G29="","",CHOOSE(WEEKDAY(B29,2),"lunedì","martedì","mercoledì","giovedì","venerdì","sabato","domenica")) | D29: =IF(G29="","",IF(INDEX(Giorni!$I$2:$I$367,G29)="A","Assenza","Giustificata")) | E29: =IF(G29="","",IF(INDEX(Giorni!$F$2:$F$367,G29)=1,"Sì","No")) | F29: =IF(G29="","",IF(E29="Sì",IF(D29="Giustificata","Conta come presenza",""),IF(INDEX(Giorni!$D$2:$D$367,G29)=1,"Festività: non conta",IF(INDEX(Giorni!$E$2:$E$367,G29)=1,"Chiusura: non conta","Fuori periodo: non conta")))) | G29: =IFERROR(MATCH(25,Giorni!$N$2:$N$367,0),"")
A30: =IF(G30="","",26) | B30: =IF(G30="","",INDEX(Giorni!$A$2:$A$367,G30)) | C30: =IF(G30="","",CHOOSE(WEEKDAY(B30,2),"lunedì","martedì","mercoledì","giovedì","venerdì","sabato","domenica")) | D30: =IF(G30="","",IF(INDEX(Giorni!$I$2:$I$367,G30)="A","Assenza","Giustificata")) | E30: =IF(G30="","",IF(INDEX(Giorni!$F$2:$F$367,G30)=1,"Sì","No")) | F30: =IF(G30="","",IF(E30="Sì",IF(D30="Giustificata","Conta come presenza",""),IF(INDEX(Giorni!$D$2:$D$367,G30)=1,"Festività: non conta",IF(INDEX(Giorni!$E$2:$E$367,G30)=1,"Chiusura: non conta","Fuori periodo: non conta")))) | G30: =IFERROR(MATCH(26,Giorni!$N$2:$N$367,0),"")
A31: =IF(G31="","",27) | B31: =IF(G31="","",INDEX(Giorni!$A$2:$A$367,G31)) | C31: =IF(G31="","",CHOOSE(WEEKDAY(B31,2),"lunedì","martedì","mercoledì","giovedì","venerdì","sabato","domenica")) | D31: =IF(G31="","",IF(INDEX(Giorni!$I$2:$I$367,G31)="A","Assenza","Giustificata")) | E31: =IF(G31="","",IF(INDEX(Giorni!$F$2:$F$367,G31)=1,"Sì","No")) | F31: =IF(G31="","",IF(E31="Sì",IF(D31="Giustificata","Conta come presenza",""),IF(INDEX(Giorni!$D$2:$D$367,G31)=1,"Festività: non conta",IF(INDEX(Giorni!$E$2:$E$367,G31)=1,"Chiusura: non conta","Fuori periodo: non conta")))) | G31: =IFERROR(MATCH(27,Giorni!$N$2:$N$367,0),"")
A32: =IF(G32="","",28) | B32: =IF(G32="","",INDEX(Giorni!$A$2:$A$367,G32)) | C32: =IF(G32="","",CHOOSE(WEEKDAY(B32,2),"lunedì","martedì","mercoledì","giovedì","venerdì","sabato","domenica")) | D32: =IF(G32="","",IF(INDEX(Giorni!$I$2:$I$367,G32)="A","Assenza","Giustificata")) | E32: =IF(G32="","",IF(INDEX(Giorni!$F$2:$F$367,G32)=1,"Sì","No")) | F32: =IF(G32="","",IF(E32="Sì",IF(D32="Giustificata","Conta come presenza",""),IF(INDEX(Giorni!$D$2:$D$367,G32)=1,"Festività: non conta",IF(INDEX(Giorni!$E$2:$E$367,G32)=1,"Chiusura: non conta","Fuori periodo: non conta")))) | G32: =IFERROR(MATCH(28,Giorni!$N$2:$N$367,0),"")
A33: =IF(G33="","",29) | B33: =IF(G33="","",INDEX(Giorni!$A$2:$A$367,G33)) | C33: =IF(G33="","",CHOOSE(WEEKDAY(B33,2),"lunedì","martedì","mercoledì","giovedì","venerdì","sabato","domenica")) | D33: =IF(G33="","",IF(INDEX(Giorni!$I$2:$I$367,G33)="A","Assenza","Giustificata")) | E33: =IF(G33="","",IF(INDEX(Giorni!$F$2:$F$367,G33)=1,"Sì","No")) | F33: =IF(G33="","",IF(E33="Sì",IF(D33="Giustificata","Conta come presenza",""),IF(INDEX(Giorni!$D$2:$D$367,G33)=1,"Festività: non conta",IF(INDEX(Giorni!$E$2:$E$367,G33)=1,"Chiusura: non conta","Fuori periodo: non conta")))) | G33: =IFERROR(MATCH(29,Giorni!$N$2:$N$367,0),"")
A34: =IF(G34="","",30) | B34: =IF(G34="","",INDEX(Giorni!$A$2:$A$367,G34)) | C34: =IF(G34="","",CHOOSE(WEEKDAY(B34,2),"lunedì","martedì","mercoledì","giovedì","venerdì","sabato","domenica")) | D34: =IF(G34="","",IF(INDEX(Giorni!$I$2:$I$367,G34)="A","Assenza","Giustificata")) | E34: =IF(G34="","",IF(INDEX(Giorni!$F$2:$F$367,G34)=1,"Sì","No")) | F34: =IF(G34="","",IF(E34="Sì",IF(D34="Giustificata","Conta come presenza",""),IF(INDEX(Giorni!$D$2:$D$367,G34)=1,"Festività: non conta",IF(INDEX(Giorni!$E$2:$E$367,G34)=1,"Chiusura: non conta","Fuori periodo: non conta")))) | G34: =IFERROR(MATCH(30,Giorni!$N$2:$N$367,0),"")
A35: =IF(G35="","",31) | B35: =IF(G35="","",INDEX(Giorni!$A$2:$A$367,G35)) | C35: =IF(G35="","",CHOOSE(WEEKDAY(B35,2),"lunedì","martedì","mercoledì","giovedì","venerdì","sabato","domenica")) | D35: =IF(G35="","",IF(INDEX(Giorni!$I$2:$I$367,G35)="A","Assenza","Giustificata")) | E35: =IF(G35="","",IF(INDEX(Giorni!$F$2:$F$367,G35)=1,"Sì","No")) | F35: =IF(G35="","",IF(E35="Sì",IF(D35="Giustificata","Conta come presenza",""),IF(INDEX(Giorni!$D$2:$D$367,G35)=1,"Festività: non conta",IF(INDEX(Giorni!$E$2:$E$367,G35)=1,"Chiusura: non conta","Fuori periodo: non conta")))) | G35: =IFERROR(MATCH(31,Giorni!$N$2:$N$367,0),"")
A36: =IF(G36="","",32) | B36: =IF(G36="","",INDEX(Giorni!$A$2:$A$367,G36)) | C36: =IF(G36="","",CHOOSE(WEEKDAY(B36,2),"lunedì","martedì","mercoledì","giovedì","venerdì","sabato","domenica")) | D36: =IF(G36="","",IF(INDEX(Giorni!$I$2:$I$367,G36)="A","Assenza","Giustificata")) | E36: =IF(G36="","",IF(INDEX(Giorni!$F$2:$F$367,G36)=1,"Sì","No")) | F36: =IF(G36="","",IF(E36="Sì",IF(D36="Giustificata","Conta come presenza",""),IF(INDEX(Giorni!$D$2:$D$367,G36)=1,"Festività: non conta",IF(INDEX(Giorni!$E$2:$E$367,G36)=1,"Chiusura: non conta","Fuori periodo: non conta")))) | G36: =IFERROR(MATCH(32,Giorni!$N$2:$N$367,0),"")
A37: =IF(G37="","",33) | B37: =IF(G37="","",INDEX(Giorni!$A$2:$A$367,G37)) | C37: =IF(G37="","",CHOOSE(WEEKDAY(B37,2),"lunedì","martedì","mercoledì","giovedì","venerdì","sabato","domenica")) | D37: =IF(G37="","",IF(INDEX(Giorni!$I$2:$I$367,G37)="A","Assenza","Giustificata")) | E37: =IF(G37="","",IF(INDEX(Giorni!$F$2:$F$367,G37)=1,"Sì","No")) | F37: =IF(G37="","",IF(E37="Sì",IF(D37="Giustificata","Conta come presenza",""),IF(INDEX(Giorni!$D$2:$D$367,G37)=1,"Festività: non conta",IF(INDEX(Giorni!$E$2:$E$367,G37)=1,"Chiusura: non conta","Fuori periodo: non conta")))) | G37: =IFERROR(MATCH(33,Giorni!$N$2:$N$367,0),"")
A38: =IF(G38="","",34) | B38: =IF(G38="","",INDEX(Giorni!$A$2:$A$367,G38)) | C38: =IF(G38="","",CHOOSE(WEEKDAY(B38,2),"lunedì","martedì","mercoledì","giovedì","venerdì","sabato","domenica")) | D38: =IF(G38="","",IF(INDEX(Giorni!$I$2:$I$367,G38)="A","Assenza","Giustificata")) | E38: =IF(G38="","",IF(INDEX(Giorni!$F$2:$F$367,G38)=1,"Sì","No")) | F38: =IF(G38="","",IF(E38="Sì",IF(D38="Giustificata","Conta come presenza",""),IF(INDEX(Giorni!$D$2:$D$367,G38)=1,"Festività: non conta",IF(INDEX(Giorni!$E$2:$E$367,G38)=1,"Chiusura: non conta","Fuori periodo: non conta")))) | G38: =IFERROR(MATCH(34,Giorni!$N$2:$N$367,0),"")
